Traceback (most recent call last):
  File "/Users/alireza/Desktop/darman/backend/venv/bin/uvicorn", line 8, in <module>
    sys.exit(main())
             ^^^^^^
  File "/Users/alireza/Desktop/darman/backend/venv/lib/python3.12/site-packages/click/core.py", line 1462, in __call__
    return self.main(*args, **kwargs)
           ^^^^^^^^^^^^^^^^^^^^^^^^^^
  File "/Users/alireza/Desktop/darman/backend/venv/lib/python3.12/site-packages/click/core.py", line 1383, in main
    rv = self.invoke(ctx)
         ^^^^^^^^^^^^^^^^
  File "/Users/alireza/Desktop/darman/backend/venv/lib/python3.12/site-packages/click/core.py", line 1246, in invoke
    return ctx.invoke(self.callback, **ctx.params)
           ^^^^^^^^^^^^^^^^^^^^^^^^^^^^^^^^^^^^^^^
  File "/Users/alireza/Desktop/darman/backend/venv/lib/python3.12/site-packages/click/core.py", line 814, in invoke
    return callback(*args, **kwargs)
           ^^^^^^^^^^^^^^^^^^^^^^^^^
  File "/Users/alireza/Desktop/darman/backend/venv/lib/python3.12/site-packages/uvicorn/main.py", line 416, in main
    run(
  File "/Users/alireza/Desktop/darman/backend/venv/lib/python3.12/site-packages/uvicorn/main.py", line 587, in run
    server.run()
  File "/Users/alireza/Desktop/darman/backend/venv/lib/python3.12/site-packages/uvicorn/server.py", line 61, in run
    return asyncio.run(self.serve(sockets=sockets))
           ^^^^^^^^^^^^^^^^^^^^^^^^^^^^^^^^^^^^^^^^
  File "/opt/anaconda3/lib/python3.12/asyncio/runners.py", line 194, in run
    return runner.run(main)
           ^^^^^^^^^^^^^^^^
  File "/opt/anaconda3/lib/python3.12/asyncio/runners.py", line 118, in run
    return self._loop.run_until_complete(task)
           ^^^^^^^^^^^^^^^^^^^^^^^^^^^^^^^^^^^
  File "/opt/anaconda3/lib/python3.12/asyncio/base_events.py", line 685, in run_until_complete
    return future.result()
           ^^^^^^^^^^^^^^^
  File "/Users/alireza/Desktop/darman/backend/venv/lib/python3.12/site-packages/uvicorn/server.py", line 68, in serve
    config.load()
  File "/Users/alireza/Desktop/darman/backend/venv/lib/python3.12/site-packages/uvicorn/config.py", line 467, in load
    self.loaded_app = import_from_string(self.app)
                      ^^^^^^^^^^^^^^^^^^^^^^^^^^^^
  File "/Users/alireza/Desktop/darman/backend/venv/lib/python3.12/site-packages/uvicorn/importer.py", line 21, in import_from_string
    module = importlib.import_module(module_str)
             ^^^^^^^^^^^^^^^^^^^^^^^^^^^^^^^^^^^
  File "/opt/anaconda3/lib/python3.12/importlib/__init__.py", line 90, in import_module
    return _bootstrap._gcd_import(name[level:], package, level)
           ^^^^^^^^^^^^^^^^^^^^^^^^^^^^^^^^^^^^^^^^^^^^^^^^^^^^
  File "<frozen importlib._bootstrap>", line 1387, in _gcd_import
  File "<frozen importlib._bootstrap>", line 1360, in _find_and_load
  File "<frozen importlib._bootstrap>", line 1331, in _find_and_load_unlocked
  File "<frozen importlib._bootstrap>", line 935, in _load_unlocked
  File "<frozen importlib._bootstrap_external>", line 995, in exec_module
  File "<frozen importlib._bootstrap>", line 488, in _call_with_frames_removed
  File "/Users/alireza/Desktop/darman/backend/main.py", line 3, in <module>
    from api.v1 import router as api_router
  File "/Users/alireza/Desktop/darman/backend/api/v1/__init__.py", line 2, in <module>
    from api.v1.admin import upload as admin_upload
  File "/Users/alireza/Desktop/darman/backend/api/v1/admin/upload.py", line 3, in <module>
    from services.excel_processor import process_insurance_excel
  File "/Users/alireza/Desktop/darman/backend/services/excel_processor.py", line 1, in <module>
    import pandas as pd
  File "/Users/alireza/Desktop/darman/backend/venv/lib/python3.12/site-packages/pandas/__init__.py", line 46, in <module>
    from pandas.core.api import (
  File "/Users/alireza/Desktop/darman/backend/venv/lib/python3.12/site-packages/pandas/core/api.py", line 1, in <module>
    from pandas._libs import (
  File "/Users/alireza/Desktop/darman/backend/venv/lib/python3.12/site-packages/pandas/_libs/__init__.py", line 18, in <module>
    from pandas._libs.interval import Interval
  File "interval.pyx", line 1, in init pandas._libs.interval
ValueError: numpy.dtype size changed, may indicate binary incompatibility. Expected 96 from C header, got 88 from PyObject
